<?xml version="1.0" ?>
<!-- =================================================================================== -->
<!-- |    This document was autogenerated by xacro from /home/pi/ros2_extras/src/rover_arm/urdf/rover_arm.urdf.xacro | -->
<!-- |    EDITING THIS FILE BY HAND IS NOT RECOMMENDED                                 | -->
<!-- =================================================================================== -->
<robot name="rover_arm">
  <!-- Base Link -->
  <link name="base_link"/>
  <!-- Base Joint -->
  <joint name="joint1_base" type="revolute">
    <parent link="base_link"/>
    <child link="link1_shoulder"/>
    <origin rpy="0 0 0" xyz="0 0 0"/>
    <axis xyz="0 0 1"/>
    <limit effort="50" lower="-2.61799" upper="2.61799" velocity="1"/>
    <!-- ±150° -->
  </joint>
  <!-- Shoulder -->
  <link name="link1_shoulder"/>
  <joint name="joint2_shoulder" type="revolute">
    <parent link="link1_shoulder"/>
    <child link="link2_elbow"/>
    <origin rpy="0 0 0" xyz="0 0 0.1"/>
    <!-- Offset for joint placement -->
    <axis xyz="0 1 0"/>
    <limit effort="50" lower="-1.57" upper="1.57" velocity="1"/>
    <!-- ±90° -->
  </joint>
  <!-- Elbow -->
  <link name="link2_elbow"/>
  <joint name="joint3_elbow" type="revolute">
    <parent link="link2_elbow"/>
    <child link="link3_wrist"/>
    <origin rpy="0 0 0" xyz="0 0 0.364"/>
    <!-- 364 mm length -->
    <axis xyz="0 1 0"/>
    <limit effort="50" lower="-1.57" upper="1.57" velocity="1"/>
    <!-- ±90° -->
  </joint>
  <!-- Wrist Up/Down -->
  <link name="link3_wrist"/>
  <joint name="joint4_wrist_pitch" type="revolute">
    <parent link="link3_wrist"/>
    <child link="link4_wrist_swivel"/>
    <origin rpy="0 0 0" xyz="0 0 0.364"/>
    <!-- 364 mm length -->
    <axis xyz="0 1 0"/>
    <limit effort="30" lower="-1.57" upper="1.57" velocity="1"/>
    <!-- ±90° -->
  </joint>
  <!-- Wrist Swivel -->
  <link name="link4_wrist_swivel"/>
  <joint name="joint5_wrist_swivel" type="revolute">
    <parent link="link4_wrist_swivel"/>
    <child link="link5_claw"/>
    <origin rpy="0 0 0" xyz="0 0 0.05"/>
    <!-- Small offset for wrist -->
    <axis xyz="0 0 1"/>
    <limit effort="30" lower="-3.14" upper="3.14" velocity="1"/>
    <!-- Full rotation -->
  </joint>
  <!-- Claw -->
  <link name="link5_claw"/>
  <joint name="joint6_claw" type="prismatic">
    <parent link="link5_claw"/>
    <child link="link6_claw_end"/>
    <origin rpy="0 0 0" xyz="0 0 0.1"/>
    <!-- Small offset for claw -->
    <axis xyz="1 0 0"/>
    <limit effort="10" lower="0.0" upper="0.05" velocity="0.1"/>
    <!-- Claw opens/closes by 5 cm -->
  </joint>
  <!-- Claw End -->
  <link name="link6_claw_end"/>
  <!-- ros2_control Configuration -->
  <ros2_control name="rover_arm_hardware" type="system">
    <hardware>
      <plugin>rover_arm::RoverArmHardware</plugin>
    </hardware>
    <joint name="joint1_base">
      <command_interface name="position"/>
      <state_interface name="position"/>
      <param name="lower_limit">-2.61799</param>
      <param name="upper_limit">2.61799</param>
    </joint>
    <joint name="joint2_shoulder">
      <command_interface name="position"/>
      <state_interface name="position"/>
    </joint>
    <joint name="joint3_elbow">
      <command_interface name="position"/>
      <state_interface name="position"/>
    </joint>
    <joint name="joint4_wrist_pitch">
      <command_interface name="position"/>
      <state_interface name="position"/>
    </joint>
    <joint name="joint5_wrist_swivel">
      <command_interface name="position"/>
      <state_interface name="position"/>
    </joint>
    <joint name="joint6_claw">
      <command_interface name="position"/>
      <state_interface name="position"/>
    </joint>
  </ros2_control>
</robot>
